<?xml version="1.0"?>
<robot name="youBot">
    <link name="base_link">
        <inertial>
            <origin rpy="-1.570796 -1.570796 0.000000" xyz="-2.000000 2.000000 0.095316" />
            <inertia izz="0.24000000208616" iyz="0.0" ixz="0.0" ixy="0.0" ixx="2.2400000691414" iyy="1.1200000345707" />
            <mass value="10.0" />
        </inertial>
        <collision name="youBot">
            <origin xyz="-1.999962 2.000000 0.063966" rpy="-1.569790 -1.570796 0.000000" />
            <geometry>
                <box size="0.097052 0.153841 0.570105" />
            </geometry>
        </collision>
        <collision name="youBot">
            <origin xyz="-2.000001 2.151208 0.058162" rpy="1.570796 3.141593 1.571802" />
            <geometry>
                <box size="0.050799 0.087727 0.357030" />
            </geometry>
        </collision>
        <collision name="youBot">
            <origin xyz="-2.000105 2.000000 0.054764" rpy="-1.569790 -1.570796 0.000000" />
            <geometry>
                <box size="0.078647 0.235196 0.541198" />
            </geometry>
        </collision>
        <collision name="youBot">
            <origin xyz="-1.999999 1.851208 0.058162" rpy="1.570796 3.141593 1.571802" />
            <geometry>
                <box size="0.050799 0.087727 0.357030" />
            </geometry>
        </collision>
        <collision name="youBot">
            <origin xyz="-2.000105 2.000000 0.056696" rpy="0.001006 -1.570796 0.000000" />
            <geometry>
                <box size="0.082511 0.247818 0.333459" />
            </geometry>
        </collision>
        <collision name="youBot">
            <origin xyz="-2.036842 1.737935 0.149951" rpy="1.537780 4.712388 1.512318" />
            <geometry>
                <box size="0.006898 0.026477 0.075109" />
            </geometry>
        </collision>
        <collision name="youBot">
            <origin xyz="-1.963842 1.738009 0.149951" rpy="0.094587 4.712340 -0.001080" />
            <geometry>
                <box size="0.006898 0.026477 0.075109" />
            </geometry>
        </collision>
        <collision name="youBot">
            <origin xyz="-2.115855 1.750856 0.149951" rpy="1.445718 4.712348 1.429845" />
            <geometry>
                <box size="0.006898 0.026477 0.075109" />
            </geometry>
        </collision>
        <collision name="youBot">
            <origin xyz="-1.883855 1.751089 0.149951" rpy="0.621780 4.712383 -0.353742" />
            <geometry>
                <box size="0.006898 0.026477 0.075109" />
            </geometry>
        </collision>
        <collision name="youBot">
            <origin xyz="-2.096032 1.926875 0.149951" rpy="-1.132640 4.712379 -1.199859" />
            <geometry>
                <box size="0.006898 0.049642 0.075109" />
            </geometry>
        </collision>
        <collision name="youBot">
            <origin xyz="-1.904032 1.927068 0.149951" rpy="-0.229130 4.712385 -0.577955" />
            <geometry>
                <box size="0.006898 0.049642 0.075109" />
            </geometry>
        </collision>
        <collision name="youBot">
            <origin xyz="-2.108939 1.834862 0.149951" rpy="-0.860322 4.712385 -0.840368" />
            <geometry>
                <box size="0.006898 0.083941 0.148350" />
            </geometry>
        </collision>
        <collision name="youBot">
            <origin xyz="-1.889939 1.835083 0.149951" rpy="-0.737276 4.712386 -0.701617" />
            <geometry>
                <box size="0.006898 0.083941 0.148350" />
            </geometry>
        </collision>
        <collision name="youBot">
            <origin xyz="-1.999956 1.851972 0.149951" rpy="-1.569790 -1.570796 0.000000" />
            <geometry>
                <box size="0.006898 0.167882 0.245830" />
            </geometry>
        </collision>
        <collision name="youBot">
            <origin xyz="-2.000270 2.166176 0.144239" rpy="3.141593 3.141592 1.866356" />
            <geometry>
                <cylinder length="0.064189240336418" radius="0.077675476670265" />
            </geometry>
        </collision>
        <collision name="youBot">
            <origin xyz="-2.001016 2.078261 0.131655" rpy="1.570796 3.141648 1.571803" />
            <geometry>
                <box size="0.050077 0.066455 0.085242" />
            </geometry>
        </collision>
        <visual name="ME_Platfo2_sub1">
            <origin xyz="-2.000105 2.000000 0.095887" rpy="-1.569790 -1.570796 0.000000" />
            <geometry>
                <mesh filename="file:///root/ros2_ws/src/robotica/urdf_omni/omni_ME_Platfo2_sub1_vis_1.dae" />
            </geometry>
            <material name="ME_Platfo2_sub1_material">
                <color rgba="0.682353 0.682353 0.682353 1.0" />
            </material>
        </visual>
        <visual name="ME_Platfo2_sub1">
            <origin xyz="-2.000105 2.000000 0.095887" rpy="-1.569790 -1.570796 0.000000" />
            <geometry>
                <mesh filename="file:///root/ros2_ws/src/robotica/urdf_omni/omni_ME_Platfo2_sub1_vis_2.dae" />
            </geometry>
            <material name="ME_Platfo2_sub1_material">
                <color rgba="0.288235 0.288235 0.288235 1.0" />
            </material>
        </visual>
        <visual name="ME_Platfo2_sub1">
            <origin xyz="-2.000105 2.000000 0.095887" rpy="-1.569790 -1.570796 0.000000" />
            <geometry>
                <mesh filename="file:///root/ros2_ws/src/robotica/urdf_omni/omni_ME_Platfo2_sub1_vis_3.dae" />
            </geometry>
            <material name="ME_Platfo2_sub1_material">
                <color rgba="1.000000 1.000000 1.000000 1.0" />
            </material>
        </visual>
        <visual name="Rectangle">
            <origin xyz="-2.000389 2.281858 0.038566" rpy="-1.656318 3.141593 0.001006" />
            <geometry>
                <mesh filename="file:///root/ros2_ws/src/robotica/urdf_omni/omni_Rectangle_vis_1.dae" />
            </geometry>
            <material name="Rectangle_material">
                <color rgba="0.682353 0.682353 0.682353 1.0" />
            </material>
        </visual>
        <visual name="Hokuyo_URG_04LX_UG01_ROS_body">
            <origin xyz="-2.000000 2.273636 0.123316" rpy="-3.141593 3.141593 -1.570796" />
            <geometry>
                <mesh filename="file:///root/ros2_ws/src/robotica/urdf_omni/omni_Hokuyo_URG_04LX_UG01_ROS_body_vis_1.dae" />
            </geometry>
            <material name="Hokuyo_URG_04LX_UG01_ROS_body_material">
                <color rgba="0.217647 0.217647 0.217647 1.0" />
            </material>
        </visual>
        <visual name="Hokuyo_URG_04LX_UG01_ROS_body">
            <origin xyz="-2.000000 2.273636 0.123316" rpy="-3.141593 3.141593 -1.570796" />
            <geometry>
                <mesh filename="file:///root/ros2_ws/src/robotica/urdf_omni/omni_Hokuyo_URG_04LX_UG01_ROS_body_vis_2.dae" />
            </geometry>
            <material name="Hokuyo_URG_04LX_UG01_ROS_body_material">
                <color rgba="0.217647 0.217647 0.217647 1.0" />
            </material>
        </visual>
        <visual name="Hokuyo_URG_04LX_UG01_ROS_body">
            <origin xyz="-2.000000 2.273636 0.123316" rpy="-3.141593 3.141593 -1.570796" />
            <geometry>
                <mesh filename="file:///root/ros2_ws/src/robotica/urdf_omni/omni_Hokuyo_URG_04LX_UG01_ROS_body_vis_3.dae" />
            </geometry>
            <material name="Hokuyo_URG_04LX_UG01_ROS_body_material">
                <color rgba="1.000000 1.000000 0.111111 1.0" />
            </material>
        </visual>
    </link>
    <joint type="continuous" name="rollingJoint_rr">
        <axis xyz="0 0 1" />
        <parent link="base_link" />
        <child link="intermediateLink_rr" />
        <origin xyz="-1.825000 1.825000 0.049935" rpy="-0.001006 1.570796 0.000000" />
    </joint>
    <link name="intermediateLink_rr">
        <inertial>
            <origin rpy="-3.141592 3.141593 3.141593" xyz="-0.000006 0.000004 0.000000" />
            <inertia izz="0.0080000003799796" iyz="0.0" ixz="0.0" ixy="0.0" ixx="0.0080000003799796" iyy="0.0080000003799796" />
            <mass value="1.0" />
        </inertial>
        <collision name="intermediateLink_rr">
            <origin xyz="-0.000006 0.000004 0.000000" rpy="-3.141592 3.141593 3.141593" />
            <geometry>
                <sphere radius="0.044999998062849" />
            </geometry>
        </collision>
        <visual name="swedishWheel_rr">
            <origin xyz="-0.000006 0.000004 0.000000" rpy="-0.000000 -1.570796 0.000000" />
            <geometry>
                <mesh filename="file:///root/ros2_ws/src/robotica/urdf_omni/omni_swedishWheel_rr_vis_1.dae" />
            </geometry>
            <material name="swedishWheel_rr_material">
                <color rgba="0.682353 0.682353 0.682353 1.0" />
            </material>
        </visual>
        <visual name="swedishWheel_rr">
            <origin xyz="-0.000006 0.000004 0.000000" rpy="-0.000000 -1.570796 0.000000" />
            <geometry>
                <mesh filename="file:///root/ros2_ws/src/robotica/urdf_omni/omni_swedishWheel_rr_vis_2.dae" />
            </geometry>
            <material name="swedishWheel_rr_material">
                <color rgba="1.000000 0.618298 0.265957 1.0" />
            </material>
        </visual>
        <visual name="swedishWheel_rr">
            <origin xyz="-0.000006 0.000004 0.000000" rpy="-0.000000 -1.570796 0.000000" />
            <geometry>
                <mesh filename="file:///root/ros2_ws/src/robotica/urdf_omni/omni_swedishWheel_rr_vis_3.dae" />
            </geometry>
            <material name="swedishWheel_rr_material">
                <color rgba="0.358824 0.358824 0.358824 1.0" />
            </material>
        </visual>
    </link>
    <joint type="continuous" name="slippingJoint_rr">
        <axis xyz="0 0 1" />
        <parent link="intermediateLink_rr" />
        <child link="wheel_respondable_rr" />
        <origin xyz="0.000000 0.000000 0.000000" rpy="2.356194 3.141593 -0.573954" />
    </joint>
    <link name="wheel_respondable_rr">
        <inertial>
            <origin rpy="-2.356195 3.141431 -0.295174" xyz="-0.000008 -0.000001 -0.000024" />
            <inertia izz="0.0080000003799796" iyz="0.0" ixz="0.0" ixy="0.0" ixx="0.0080000003799796" iyy="0.0080000003799796" />
            <mass value="1.0" />
        </inertial>
        <collision name="wheel_respondable_rr">
            <origin xyz="-0.000008 -0.000001 -0.000024" rpy="-2.356195 3.141431 -0.295174" />
            <geometry>
                <sphere radius="0.050000000745058" />
            </geometry>
        </collision>
    </link>
    <joint type="continuous" name="rollingJoint_rl">
        <axis xyz="0 0 1" />
        <parent link="base_link" />
        <child link="intermediateLink_rl" />
        <origin xyz="-2.175000 1.825000 0.049935" rpy="-0.001006 1.570796 0.000000" />
    </joint>
    <link name="intermediateLink_rl">
        <inertial>
            <origin rpy="3.141590 3.141607 0.000000" xyz="-0.000009 -0.000001 0.000003" />
            <inertia izz="0.0080000003799796" iyz="0.0" ixz="0.0" ixy="0.0" ixx="0.0080000003799796" iyy="0.0080000003799796" />
            <mass value="1.0" />
        </inertial>
        <collision name="intermediateLink_rl">
            <origin xyz="-0.000009 -0.000001 0.000003" rpy="3.141590 3.141607 0.000000" />
            <geometry>
                <sphere radius="0.044999998062849" />
            </geometry>
        </collision>
        <visual name="swedishWheel_rl">
            <origin xyz="-0.000009 -0.000001 0.000003" rpy="-2.948969 4.712375 2.948969" />
            <geometry>
                <mesh filename="file:///root/ros2_ws/src/robotica/urdf_omni/omni_swedishWheel_rl_vis_1.dae" />
            </geometry>
            <material name="swedishWheel_rl_material">
                <color rgba="0.682353 0.682353 0.682353 1.0" />
            </material>
        </visual>
        <visual name="swedishWheel_rl">
            <origin xyz="-0.000009 -0.000001 0.000003" rpy="-2.948969 4.712375 2.948969" />
            <geometry>
                <mesh filename="file:///root/ros2_ws/src/robotica/urdf_omni/omni_swedishWheel_rl_vis_2.dae" />
            </geometry>
            <material name="swedishWheel_rl_material">
                <color rgba="1.000000 0.618298 0.265957 1.0" />
            </material>
        </visual>
        <visual name="swedishWheel_rl">
            <origin xyz="-0.000009 -0.000001 0.000003" rpy="-2.948969 4.712375 2.948969" />
            <geometry>
                <mesh filename="file:///root/ros2_ws/src/robotica/urdf_omni/omni_swedishWheel_rl_vis_3.dae" />
            </geometry>
            <material name="swedishWheel_rl_material">
                <color rgba="0.358824 0.358824 0.358824 1.0" />
            </material>
        </visual>
    </link>
    <joint type="continuous" name="slippingJoint_rl">
        <axis xyz="0 0 1" />
        <parent link="intermediateLink_rl" />
        <child link="wheel_respondable_rl" />
        <origin xyz="-0.000000 0.000000 -0.000000" rpy="2.356194 3.141593 -3.112947" />
    </joint>
    <link name="wheel_respondable_rl">
        <inertial>
            <origin rpy="2.356193 3.141740 0.058622" xyz="-0.000011 -0.000003 0.000022" />
            <inertia izz="0.0080000003799796" iyz="0.0" ixz="0.0" ixy="0.0" ixx="0.0080000003799796" iyy="0.0080000003799796" />
            <mass value="1.0" />
        </inertial>
        <collision name="wheel_respondable_rl">
            <origin xyz="-0.000011 -0.000003 0.000022" rpy="2.356193 3.141740 0.058622" />
            <geometry>
                <sphere radius="0.050000000745058" />
            </geometry>
        </collision>
    </link>
    <joint type="revolute" name="Joint">
        <axis xyz="0 0 1" />
        <limit effort="2.5" lower="-0.17453292012215" velocity="6.2831854820251" upper="0.17453292012215" />
        <parent link="base_link" />
        <child link="Rectangle0" />
        <origin xyz="-2.000335 2.228000 0.049935" rpy="-1.570796 3.141593 -3.140587" />
    </joint>
    <link name="Rectangle0">
        <inertial>
            <origin rpy="1.569564 3.141593 -3.141307" xyz="-0.000004 0.000019 0.000000" />
            <inertia izz="0.080800086259842" iyz="0.0" ixz="0.0" ixy="0.0" ixx="0.0024000031407923" iyy="0.080799981951714" />
            <mass value="2.0" />
        </inertial>
        <collision name="Rectangle0">
            <origin xyz="-0.000004 0.000019 0.000000" rpy="1.569564 3.141593 -3.141307" />
            <geometry>
                <box size="0.200000 0.030000 0.030000" />
            </geometry>
        </collision>
    </link>
    <joint type="continuous" name="rollingJoint_fl">
        <axis xyz="0 0 1" />
        <parent link="Rectangle0" />
        <child link="intermediateLink_fl" />
        <origin xyz="-0.174722 0.000034 0.052825" rpy="1.570797 3.142826 1.571082" />
    </joint>
    <link name="intermediateLink_fl">
        <inertial>
            <origin rpy="-3.141592 3.141593 -3.141593" xyz="0.000002 -0.000006 0.000000" />
            <inertia izz="0.0080000003799796" iyz="0.0" ixz="0.0" ixy="0.0" ixx="0.0080000003799796" iyy="0.0080000003799796" />
            <mass value="1.0" />
        </inertial>
        <collision name="intermediateLink_fl">
            <origin xyz="0.000002 -0.000006 0.000000" rpy="-3.141592 3.141593 -3.141593" />
            <geometry>
                <sphere radius="0.044999998062849" />
            </geometry>
        </collision>
        <visual name="swedishWheel_fl">
            <origin xyz="0.000002 -0.000005 0.000000" rpy="0.000000 -1.570796 0.000000" />
            <geometry>
                <mesh filename="file:///root/ros2_ws/src/robotica/urdf_omni/omni_swedishWheel_fl_vis_1.dae" />
            </geometry>
            <material name="swedishWheel_fl_material">
                <color rgba="0.682353 0.682353 0.682353 1.0" />
            </material>
        </visual>
        <visual name="swedishWheel_fl">
            <origin xyz="0.000002 -0.000005 0.000000" rpy="0.000000 -1.570796 0.000000" />
            <geometry>
                <mesh filename="file:///root/ros2_ws/src/robotica/urdf_omni/omni_swedishWheel_fl_vis_2.dae" />
            </geometry>
            <material name="swedishWheel_fl_material">
                <color rgba="1.000000 0.618298 0.265957 1.0" />
            </material>
        </visual>
        <visual name="swedishWheel_fl">
            <origin xyz="0.000002 -0.000005 0.000000" rpy="0.000000 -1.570796 0.000000" />
            <geometry>
                <mesh filename="file:///root/ros2_ws/src/robotica/urdf_omni/omni_swedishWheel_fl_vis_3.dae" />
            </geometry>
            <material name="swedishWheel_fl_material">
                <color rgba="0.358824 0.358824 0.358824 1.0" />
            </material>
        </visual>
    </link>
    <joint type="continuous" name="slippingJoint_fl">
        <axis xyz="0 0 1" />
        <parent link="intermediateLink_fl" />
        <child link="wheel_respondable_fl" />
        <origin xyz="0.000000 0.000000 -0.000000" rpy="2.356195 3.141593 -1.292044" />
    </joint>
    <link name="wheel_respondable_fl">
        <inertial>
            <origin rpy="-2.356195 3.141533 2.067038" xyz="-0.000017 0.000038 -0.000006" />
            <inertia izz="0.0080000003799796" iyz="0.0" ixz="0.0" ixy="0.0" ixx="0.0080000003799796" iyy="0.0080000003799796" />
            <mass value="1.0" />
        </inertial>
        <collision name="wheel_respondable_fl">
            <origin xyz="-0.000017 0.000038 -0.000006" rpy="-2.356195 3.141533 2.067038" />
            <geometry>
                <sphere radius="0.050000000745058" />
            </geometry>
        </collision>
    </link>
    <joint type="continuous" name="rollingJoint_fr">
        <axis xyz="0 0 1" />
        <parent link="Rectangle0" />
        <child link="intermediateLink_fr" />
        <origin xyz="0.175278 0.000135 0.053177" rpy="1.570797 3.142826 1.571082" />
    </joint>
    <link name="intermediateLink_fr">
        <inertial>
            <origin rpy="-3.141581 3.141518 3.141592" xyz="0.000078 -0.000012 0.000005" />
            <inertia izz="0.0080000003799796" iyz="0.0" ixz="0.0" ixy="0.0" ixx="0.0080000003799796" iyy="0.0080000003799796" />
            <mass value="1.0" />
        </inertial>
        <collision name="intermediateLink_fr">
            <origin xyz="0.000078 -0.000012 0.000005" rpy="-3.141581 3.141518 3.141592" />
            <geometry>
                <sphere radius="0.044999998062849" />
            </geometry>
        </collision>
        <visual name="swedishWheel_fr">
            <origin xyz="0.000078 -0.000012 0.000005" rpy="-2.981611 4.712313 2.981611" />
            <geometry>
                <mesh filename="file:///root/ros2_ws/src/robotica/urdf_omni/omni_swedishWheel_fr_vis_1.dae" />
            </geometry>
            <material name="swedishWheel_fr_material">
                <color rgba="0.682353 0.682353 0.682353 1.0" />
            </material>
        </visual>
        <visual name="swedishWheel_fr">
            <origin xyz="0.000078 -0.000012 0.000005" rpy="-2.981611 4.712313 2.981611" />
            <geometry>
                <mesh filename="file:///root/ros2_ws/src/robotica/urdf_omni/omni_swedishWheel_fr_vis_2.dae" />
            </geometry>
            <material name="swedishWheel_fr_material">
                <color rgba="1.000000 0.618298 0.265957 1.0" />
            </material>
        </visual>
        <visual name="swedishWheel_fr">
            <origin xyz="0.000078 -0.000012 0.000005" rpy="-2.981611 4.712313 2.981611" />
            <geometry>
                <mesh filename="file:///root/ros2_ws/src/robotica/urdf_omni/omni_swedishWheel_fr_vis_3.dae" />
            </geometry>
            <material name="swedishWheel_fr_material">
                <color rgba="0.358824 0.358824 0.358824 1.0" />
            </material>
        </visual>
    </link>
    <joint type="continuous" name="slippingJoint_fr">
        <axis xyz="0 0 1" />
        <parent link="intermediateLink_fr" />
        <child link="wheel_respondable_fr" />
        <origin xyz="-0.000000 0.000000 -0.000000" rpy="2.356193 3.141592 -2.589578" />
    </joint>
    <link name="wheel_respondable_fr">
        <inertial>
            <origin rpy="2.356194 3.141687 0.856790" xyz="0.000030 0.000030 0.000010" />
            <inertia izz="0.0080000003799796" iyz="0.0" ixz="0.0" ixy="0.0" ixx="0.0080000003799796" iyy="0.0080000003799796" />
            <mass value="1.0" />
        </inertial>
        <collision name="wheel_respondable_fr">
            <origin xyz="0.000030 0.000030 0.000010" rpy="2.356194 3.141687 0.856790" />
            <geometry>
                <sphere radius="0.050000000745058" />
            </geometry>
        </collision>
    </link>
</robot>
